Workbook

Sheet Assumptions
A1: RISHCA OS — FINANCIAL MODEL ASSUMPTIONS
A2: All blue values are editable inputs. Black values are calculated.
B4: Q1 2026 | C4: Q2 2026 | D4: Q3 2026 | E4: Q4 2026 | F4: FY 2026 | G4: FY 2027 | H4: FY 2028 | I4: FY 2029
A6: PRICING (Monthly)
A7: Light Plan ($/mo) | B7: 100
A8: Growth Plan ($/mo) | B8: 180
A9: Pro Plan ($/mo) | B9: 350
A10: Enterprise Plan ($/mo) | B10: 999
A12: NEW CUSTOMERS PER QUARTER (Pre-Fund)
A13: Light — New | B13: 0 | C13: 0 | D13: 0 | E13: 2
A14: Growth — New | B14: 0 | C14: 0 | D14: 2 | E14: 2
A15: Pro — New | B15: 0 | C15: 2 | D15: 3 | E15: 5
A16: Enterprise — New | B16: 0 | C16: 1 | D16: 1 | E16: 0
A17: Total New (Pre-Fund) | B17: =SUM(B13:B16) -> 0 | C17: =SUM(C13:C16) -> 3 | D17: =SUM(D13:D16) -> 6 | E17: =SUM(E13:E16) -> 9
A19: POST-FUND ANNUAL NEW CUSTOMERS
A20: Light — New | F20: =SUM(B13:E13) -> 2 | G20: 120 | H20: 400 | I20: 800
A21: Growth — New | F21: =SUM(B14:E14) -> 4 | G21: 60 | H21: 200 | I21: 500
A22: Pro — New | F22: =SUM(B15:E15) -> 10 | G22: 30 | H22: 80 | I22: 200
A23: Enterprise — New | F23: =SUM(B16:E16) -> 2 | G23: 8 | H23: 20 | I23: 50
A24: Total New / Year | F24: =SUM(F20:F23) -> 18 | G24: =SUM(G20:G23) -> 218 | H24: =SUM(H20:H23) -> 700 | I24: =SUM(I20:I23) -> 1550
A26: CHURN ASSUMPTIONS
A27: Monthly Churn Rate | B27: 0.03
A29: PEOPLE COST — PRE-FUND ($/mo)
A30: Founder Salary ($/mo) | B30: 1200 | C30: 1300 | D30: 1500 | E30: 2000
A31: Note: Current team costs covered separately (Shezlong)
A33: PEOPLE COST — POST-FUND ($/mo per person)
A34: CEO (Aly) | B34: 4000
A35: CCO (Co-Founder) | B35: 3000
A36: Engineering Manager | B36: 3000
A37: Senior Backend Developer | B37: 1500
A38: Junior Developer | B38: 700
A39: Full-Time UAT | B39: 700
A40: PM / Growth Marketer (optional) | B40: 1000
A41: Monthly Marketing Freelancer | B41: 500
A42: Business Development Manager | B42: 1000
A43: Total Monthly Team Cost (Post-Fund) | B43: =SUM(B34:B42) -> 15400
A45: TOOLS & INFRASTRUCTURE ($/mo)
A46: Lovable | B46: 300
A47: Git + AI Tools | B47: 100
A48: GCP (Q1 base, grows) | B48: 100
...

Sheet P&L
A1: RISHCA OS — PROFIT & LOSS
B3: Q1 2026 | C3: Q2 2026 | D3: Q3 2026 | E3: Q4 2026 | F3: FY 2026 | G3: FY 2027 | H3: FY 2028 | I3: FY 2029
A5: REVENUE
A6: Light Revenue | B6: 0 | C6: 0 | D6: 0 | E6: =Assumptions!B7*2*1.5 -> 300 | F6: =SUM(B6:E6) -> 300 | G6: =(2+120/2)*Assumptions!B7*12 -> 74400 | H6: =(122+400/2)*Assumptions!B7*12 -> 386400 | I6: =(522+800/2)*Assumptions!B7*12 -> 1106400
A7: Growth Revenue | B7: 0 | C7: 0 | D7: =Assumptions!B8*2*1.5 -> 540 | E7: =Assumptions!B8*(2*3+2*1.5) -> 1620 | F7: =SUM(B7:E7) -> 2160 | G7: =(4+60/2)*Assumptions!B8*12 -> 73440 | H7: =(64+200/2)*Assumptions!B8*12 -> 354240 | I7: =(264+500/2)*Assumptions!B8*12 -> 1110240
A8: Pro Revenue | B8: 0 | C8: =Assumptions!B9*2*1 -> 700 | D8: =Assumptions!B9*(2*3+3*1.5) -> 3675 | E8: =Assumptions!B9*(5*3+5*1.5) -> 7875 | F8: =SUM(B8:E8) -> 12250 | G8: =(10+30/2)*Assumptions!B9*12 -> 105000 | H8: =(40+80/2)*Assumptions!B9*12 -> 336000 | I8: =(120+200/2)*Assumptions!B9*12 -> 924000
A9: Enterprise Revenue | B9: 0 | C9: =Assumptions!B10*1*1 -> 999 | D9: =Assumptions!B10*(1*3+1*1.5) -> 4495.5 | E9: =Assumptions!B10*2*3 -> 5994 | F9: =SUM(B9:E9) -> 11488.5 | G9: =(2+8/2)*Assumptions!B10*12 -> 71928 | H9: =(10+20/2)*Assumptions!B10*12 -> 239760 | I9: =(30+50/2)*Assumptions!B10*12 -> 659340
A10: Influencer Campaign Revenue | B10: 0 | C10: 9000 | D10: 5000 | E10: 8000 | F10: =SUM(B10:E10) -> 22000 | G10: 60000 | H10: 120000 | I10: 200000
A11: OTP Transaction Revenue | B11: 0 | C11: 0 | D11: 100 | E11: 500 | F11: =SUM(B11:E11) -> 600 | G11: 5000 | H11: 15000 | I11: 40000
A13: TOTAL REVENUE | B13: =SUM(B6:B11) -> 0 | C13: =SUM(C6:C11) -> 10699 | D13: =SUM(D6:D11) -> 13810.5 | E13: =SUM(E6:E11) -> 24289 | F13: =SUM(F6:F11) -> 48798.5 | G13: =SUM(G6:G11) -> 389768 | H13: =SUM(H6:H11) -> 1451400 | I13: =SUM(I6:I11) -> 4039980
A15: COSTS
A16: People — Founder | B16: =Assumptions!B30*3 -> 3600 | C16: =Assumptions!C30*3 -> 3900 | D16: =Assumptions!D30*3 -> 4500 | E16: =Assumptions!E30*3 -> 6000 | F16: =SUM(B16:E16) -> 18000 | G16: =Assumptions!B34*12 -> 48000 | H16: =Assumptions!B34*12 -> 48000 | I16: =Assumptions!B34*12 -> 48000
A17: People — Post-Fund Team (excl CEO) | B17: 0 | C17: 0 | D17: 0 | E17: 0 | F17: =SUM(B17:E17) -> 0 | G17: =(Assumptions!B43-Assumptions!B34)*12 -> 136800 | H17: =G17*1.15 -> 157320 | I17: =H17*1.2 -> 188784
A18: Tools & Infrastructure | B18: =Assumptions!B52*3*1 -> 1800 | C18: =Assumptions!B52*3*1.15 -> 2070 | D18: =Assumptions!B52*3*1.3 -> 2340 | E18: =Assumptions!B52*3*1.45 -> 2610 | F18: =SUM(B18:E18) -> 8820 | G18: =Assumptions!B52*12*1.5 -> 10800 | H18: =G18*1.8 -> 19440 | I18: =H18*2 -> 38880
A19: CAC / Sales & Marketing | B19: 0 | C19: 500 | D19: 750 | E19: 1500 | F19: =SUM(B19:E19) -> 2750 | G19: 35000 | H19: 85000 | I19: 180000
A20: Office & Operations | B20: 0 | C20: 0 | D20: 0 | E20: 0 | F20: =SUM(B20:E20) -> 0 | G20: 18000 | H20: 24000 | I20: 30000
A21: Company Setup & Legal (one-time) | B21: 0 | C21: 0 | D21: 0 | E21: 0 | F21: =SUM(B21:E21) -> 0 | G21: 5000 | H21: 8000 | I21: 5000
A22: Ads & Paid Marketing | B22: 0 | C22: 0 | D22: 500 | E22: 1500 | F22: =SUM(B22:E22) -> 2000 | G22: 18000 | H22: 36000 | I22: 60000
A24: TOTAL COSTS | B24: =SUM(B16:B22) -> 5400 | C24: =SUM(C16:C22) -> 6470 | D24: =SUM(D16:D22) -> 8090 | E24: =SUM(E16:E22) -> 11610 | F24: =SUM(F16:F22) -> 31570 | G24: =SUM(G16:G22) -> 271600 | H24: =SUM(H16:H22) -> 377760 | I24: =SUM(I16:I22) -> 550664
A26: NET INCOME / (LOSS) | B26: =B13-B24 -> -5400 | C26: =C13-C24 -> 4229 | D26: =D13-D24 -> 5720.5 | E26: =E13-E24 -> 12679 | F26: =F13-F24 -> 17228.5 | G26: =G13-G24 -> 118168 | H26: =H13-H24 -> 1073640 | I26: =I13-I24 -> 3489316
A28: CASH FLOW
A29: Opening Cash | B29: 0 | C29: =B31 -> -5400 | D29: =C31 -> -1171 | E29: =D31 -> 4549.5 | F29: =B29 -> 0 | G29: =F31+Assumptions!B63 -> 1017228.5 | H29: =G31 -> 1135396.5 | I29: =H31 -> 2209036.5
A30: Net Cash Flow | B30: =B26 -> -5400 | C30: =C26 -> 4229 | D30: =D26 -> 5720.5 | E30: =E26 -> 12679 | F30: =F26 -> 17228.5 | G30: =G26 -> 118168 | H30: =H26 -> 1073640 | I30: =I26 -> 3489316
A31: Closing Cash | B31: =B29+B30 -> -5400 | C31: =C29+C30 -> -1171 | D31: =D29+D30 -> 4549.5 | E31: =E29+E30 -> 17228.5 | F31: =F29+F30 -> 17228.5 | G31: =G29+G30 -> 1135396.5 | H31: =H29+H30 -> 2209036.5 | I31: =I29+I30 -> 5698352.5
A32: Monthly Burn Rate | B32: =IF(B26<0,ABS(B26)/3,0) -> 1800 | C32: =IF(C26<0,ABS(C26)/3,0) -> 0 | D32: =IF(D26<0,ABS(D26)/3,0) -> 0 | E32: =IF(E26<0,ABS(E26)/3,0) -> 0 | F32: =IF(F26<0,ABS(F26)/12,0) -> 0 | G32: =IF(G26<0,ABS(G26)/12,0) -> 0 | H32: =IF(H26<0,ABS(H26)/12,0) -> 0 | I32: =IF(I26<0,ABS(I26)/12,0) -> 0
A33: Runway (months) | B33: =IF(B32>0,B31/B32,999) -> -3 | C33: =IF(C32>0,C31/C32,999) -> 999 | D33: =IF(D32>0,D31/D32,999) -> 999 | E33: =IF(E32>0,E31/E32,999) -> 999 | F33: =IF(F32>0,F31/F32,999) -> 999 | G33: =IF(G32>0,G31/G32,999) -> 999 | H33: =IF(H32>0,H31/H32,999) -> 999 | I33: =IF(I32>0,I31/I32,999) -> 999

Sheet Customer Waterfall
A1: CUSTOMER WATERFALL BY PLAN TYPE
B3: Q1 2026 | C3: Q2 2026 | D3: Q3 2026 | E3: Q4 2026 | F3: FY 2026 | G3: FY 2027 | H3: FY 2028 | I3: FY 2029
A5: LIGHT PLAN
A6: Opening Light Customers | B6: 0 | C6: =B9 -> 0 | D6: =C9 -> 0 | E6: =D9 -> 0
A7: New Light Customers | B7: =Assumptions!B13 -> 0 | C7: =Assumptions!C13 -> 0 | D7: =Assumptions!D13 -> 0 | E7: =Assumptions!E13 -> 2
A8: Churned Light | B8: =-ROUND(B6*Assumptions!B27,0) -> 0 | C8: =-ROUND(C6*Assumptions!B27,0) -> 0 | D8: =-ROUND(D6*Assumptions!B27,0) -> 0 | E8: =-ROUND(E6*Assumptions!B27,0) -> 0
A9: Closing Light Customers | B9: =B6+B7+B8 -> 0 | C9: =C6+C7+C8 -> 0 | D9: =D6+D7+D8 -> 0 | E9: =E6+E7+E8 -> 2 | F9: =E9 -> 2 | G9: =ROUND(F9*(1-Assumptions!B27*12)+Assumptions!G20,0) -> 121 | H9: =ROUND(G9*(1-Assumptions!B27*12)+Assumptions!H20,0) -> 477 | I9: =ROUND(H9*(1-Assumptions!B27*12)+Assumptions!I20,0) -> 1105
A11: GROWTH PLAN
A12: Opening Growth Customers | B12: 0 | C12: =B15 -> 0 | D12: =C15 -> 0 | E12: =D15 -> 2
A13: New Growth Customers | B13: =Assumptions!B14 -> 0 | C13: =Assumptions!C14 -> 0 | D13: =Assumptions!D14 -> 2 | E13: =Assumptions!E14 -> 2
A14: Churned Growth | B14: =-ROUND(B12*Assumptions!B27,0) -> 0 | C14: =-ROUND(C12*Assumptions!B27,0) -> 0 | D14: =-ROUND(D12*Assumptions!B27,0) -> 0 | E14: =-ROUND(E12*Assumptions!B27,0) -> 0
A15: Closing Growth Customers | B15: =B12+B13+B14 -> 0 | C15: =C12+C13+C14 -> 0 | D15: =D12+D13+D14 -> 2 | E15: =E12+E13+E14 -> 4 | F15: =E15 -> 4 | G15: =ROUND(F15*(1-Assumptions!B27*12)+Assumptions!G21,0) -> 63 | H15: =ROUND(G15*(1-Assumptions!B27*12)+Assumptions!H21,0) -> 240 | I15: =ROUND(H15*(1-Assumptions!B27*12)+Assumptions!I21,0) -> 654
A17: PRO PLAN
A18: Opening Pro Customers | B18: 0 | C18: =B21 -> 0 | D18: =C21 -> 2 | E18: =D21 -> 5
A19: New Pro Customers | B19: =Assumptions!B15 -> 0 | C19: =Assumptions!C15 -> 2 | D19: =Assumptions!D15 -> 3 | E19: =Assumptions!E15 -> 5
A20: Churned Pro | B20: =-ROUND(B18*Assumptions!B27,0) -> 0 | C20: =-ROUND(C18*Assumptions!B27,0) -> 0 | D20: =-ROUND(D18*Assumptions!B27,0) -> 0 | E20: =-ROUND(E18*Assumptions!B27,0) -> 0
A21: Closing Pro Customers | B21: =B18+B19+B20 -> 0 | C21: =C18+C19+C20 -> 2 | D21: =D18+D19+D20 -> 5 | E21: =E18+E19+E20 -> 10 | F21: =E21 -> 10 | G21: =ROUND(F21*(1-Assumptions!B27*12)+Assumptions!G22,0) -> 36 | H21: =ROUND(G21*(1-Assumptions!B27*12)+Assumptions!H22,0) -> 103 | I21: =ROUND(H21*(1-Assumptions!B27*12)+Assumptions!I22,0) -> 266
A23: ENTERPRISE PLAN
A24: Opening Enterprise Customers | B24: 0 | C24: =B27 -> 0 | D24: =C27 -> 1 | E24: =D27 -> 2
A25: New Enterprise Customers | B25: =Assumptions!B16 -> 0 | C25: =Assumptions!C16 -> 1 | D25: =Assumptions!D16 -> 1 | E25: =Assumptions!E16 -> 0
A26: Churned Enterprise | B26: =-ROUND(B24*Assumptions!B27,0) -> 0 | C26: =-ROUND(C24*Assumptions!B27,0) -> 0 | D26: =-ROUND(D24*Assumptions!B27,0) -> 0 | E26: =-ROUND(E24*Assumptions!B27,0) -> 0
A27: Closing Enterprise Customers | B27: =B24+B25+B26 -> 0 | C27: =C24+C25+C26 -> 1 | D27: =D24+D25+D26 -> 2 | E27: =E24+E25+E26 -> 2 | F27: =E27 -> 2 | G27: =ROUND(F27*(1-Assumptions!B27*12)+Assumptions!G23,0) -> 9 | H27: =ROUND(G27*(1-Assumptions!B27*12)+Assumptions!H23,0) -> 26 | I27: =ROUND(H27*(1-Assumptions!B27*12)+Assumptions!I23,0) -> 67
A29: TOTAL CUSTOMERS
A30: Total Active Customers | B30: =B9+B15+B21+B27 -> 0 | C30: =C9+C15+C21+C27 -> 3 | D30: =D9+D15+D21+D27 -> 9 | E30: =E9+E15+E21+E27 -> 18 | F30: =F9+F15+F21+F27 -> 18 | G30: =G9+G15+G21+G27 -> 229 | H30: =H9+H15+H21+H27 -> 846 | I30: =I9+I15+I21+I27 -> 2092

Sheet Geographic Split
A1: GEOGRAPHIC CUSTOMER SPLIT
B3: FY 2026 | C3: FY 2027 | D3: FY 2028 | E3: FY 2029
A5: EGYPT (Launch Market)
A6: Egypt — Light | B6: 20 | C6: 100 | D6: 200 | E6: 350
A7: Egypt — Growth | B7: 10 | C7: 40 | D7: 100 | E7: 200
A8: Egypt — Pro | B8: 11 | C8: 25 | D8: 50 | E8: 100
A9: Egypt — Enterprise | B9: 2 | C9: 5 | D9: 10 | E9: 20
A10: Egypt Total | B10: =SUM(B6:B9) -> 43 | C10: =SUM(C6:C9) -> 170 | D10: =SUM(D6:D9) -> 360 | E10: =SUM(E6:E9) -> 670
A12: GCC (2027 Launch — UAE & KSA)
A13: GCC — Light | B13: 0 | C13: 20 | D13: 150 | E13: 350
A14: GCC — Growth | B14: 0 | C14: 15 | D14: 80 | E14: 250
A15: GCC — Pro | B15: 0 | C15: 5 | D15: 25 | E15: 80
A16: GCC — Enterprise | B16: 0 | C16: 3 | D16: 8 | E16: 25
A17: GCC Total | B17: =SUM(B13:B16) -> 0 | C17: =SUM(C13:C16) -> 43 | D17: =SUM(D13:D16) -> 263 | E17: =SUM(E13:E16) -> 705
A19: NORTH AFRICA (2028 Launch)
A20: N. Africa — Light | B20: 0 | C20: 0 | D20: 50 | E20: 100
A21: N. Africa — Growth | B21: 0 | C21: 0 | D21: 20 | E21: 50
A22: N. Africa — Pro | B22: 0 | C22: 0 | D22: 5 | E22: 20
A23: N. Africa — Enterprise | B23: 0 | C23: 0 | D23: 2 | E23: 5
A24: N. Africa Total | B24: =SUM(B20:B23) -> 0 | C24: =SUM(C20:C23) -> 0 | D24: =SUM(D20:D23) -> 77 | E24: =SUM(E20:E23) -> 175
A26: GLOBAL TOTAL
A27: Total Customers (All Regions) | B27: =B10+B17+B24 -> 43 | C27: =C10+C17+C24 -> 213 | D27: =D10+D17+D24 -> 700 | E27: =E10+E17+E24 -> 1550

Sheet Team Plan
A1: TEAM & HIRING PLAN
A3: Role | B3: Pre-Fund (2026) | C3: Post-Fund (2027) | D3: Scale (2028-29)
A5: Aly Zeineldin (CEO) | B5: Solo Founder | C5: $4,000/mo | D5: $5,000/mo
A6: CCO (Co-Founder) | B6: Searching | C6: $3,000/mo | D6: $4,000/mo
A7: Engineering Manager | B7: — | C7: $3,000/mo | D7: $3,500/mo
A8: Senior Backend Dev | B8: — | C8: $1,500/mo | D8: $2,000/mo
A9: Junior Developer | B9: — | C9: $700/mo | D9: $1,000/mo
A10: Full-Time UAT | B10: — | C10: $700/mo | D10: $900/mo
A11: PM / Growth Marketer | B11: — | C11: $1,000/mo (optional) | D11: $1,500/mo
A12: BD Manager | B12: — | C12: $1,000/mo | D12: $1,500/mo
A13: Marketing Freelancer | B13: — | C13: $500/mo | D13: $500/mo
A15: Current Team (Shezlong shared)
A16: 3× Full Stack (Amr, Yassin, Bahaa) | B16: Shared cost | C16: Transition to Rishca | D16: Full-time Rishca
A17: 1× Jr Backend (Anas Emad) | B17: Shared cost | C17: Full-time | D17: Full-time
A18: 1× UAT (Tarek Mohamed) | B18: Shared cost | C18: Full-time | D18: Full-time
A19: 1× Product (Aml Hamdy) | B19: Shared cost | C19: Full-time | D19: Full-time
A20: 1× UX (Nada Amin) | B20: Shared cost | C20: Full-time | D20: Full-time
