Workbook

Sheet Team Roster
A1: Name | B1: Role | C1: Employment Type | D1: Hourly Rate (EGP) | E1: Monthly Salary (EGP) | F1: Start Date | G1: End Date | H1: Status
A2: Rana El Sobky | B2: Developer | C2: Hourly | D2: 250 | F2: 2025-01-01 | G2: 2025-08-31 | H2: Inactive
A3: Abaza | B3: Developer | C3: Hourly | D3: 400 | F3: 2025-01-01 | G3: 2025-06-30 | H3: Inactive
A4: Alaa Ashraf | B4: Developer | C4: Hourly | D4: 100 | F4: 2025-01-01 | H4: Active
A5: Nada Amin | B5: Developer | C5: Hourly | D5: 150 | F5: 2025-01-01 | H5: Active
A6: Ahmed Hamdy | B6: Developer | C6: Hourly | D6: 500 | F6: 2025-01-01 | H6: Mostly Inactive
A7: Yasseen Nouh | B7: Developer | C7: Hourly | D7: 900 | F7: 2025-01-01 | H7: Active
A8: Amr Tarek | B8: Developer | C8: Hourly | D8: 350 | F8: 2025-01-01 | H8: Active
A9: Tarek Mohamed | B9: Developer | C9: Hourly | D9: 150 | F9: 2025-01-01 | H9: Active
A10: Amal Hamdy | B10: Developer | C10: Fulltime | E10: 6000 | F10: 2025-01-01 | H10: Active
A11: Anas Emad | B11: Developer | C11: Part-time + Hourly | D11: 170.07 | E11: 12000 | F11: 2025-12-01 | H11: Active
A12: Bahaa Mohamed | B12: Developer | C12: Part-time + Hourly | E12: 30000 | F12: 2026-02-15 | H12: Active

Sheet Time Log
A1: # | B1: Year | C1: Month | D1: Name | E1: Employment Type | F1: Hourly Rate (EGP) | G1: Hours | H1: Amount (EGP) | I1: Payment Status
A2: 1 | B2: 2025 | C2: March | D2: Rana El Sobky | E2: Hourly | F2: 150 | G2: 18.25 | H2: =F2*G2 -> 2737.5 | I2: Transferred
A3: 2 | B3: 2025 | C3: March | D3: Abaza | E3: Hourly | F3: 250 | G3: 4.5 | H3: =F3*G3 -> 1125 | I3: Transferred
A4: 3 | B4: 2025 | C4: March | D4: Alaa Ashraf | E4: Hourly | F4: 100 | G4: 0 | H4: =F4*G4 -> 0 | I4: Transferred
A5: 4 | B5: 2025 | C5: April | D5: Rana El Sobky | E5: Hourly | F5: 250 | G5: 6 | H5: =F5*G5 -> 1500 | I5: Transferred
A6: 5 | B6: 2025 | C6: April | D6: Abaza | E6: Hourly | F6: 400 | G6: 3.5 | H6: =F6*G6 -> 1400 | I6: Transferred
A7: 6 | B7: 2025 | C7: April | D7: Alaa Ashraf | E7: Hourly | F7: 100 | G7: 7.25 | H7: =F7*G7 -> 725 | I7: Transferred
A8: 7 | B8: 2025 | C8: April | D8: Nada Amin | E8: Hourly | F8: 150 | G8: 17 | H8: =F8*G8 -> 2550 | I8: Transferred
A9: 8 | B9: 2025 | C9: April | D9: Ahmed Hamdy | E9: Hourly | F9: 500 | G9: 9 | H9: =F9*G9 -> 4500 | I9: Transferred
A10: 9 | B10: 2025 | C10: May | D10: Rana El Sobky | E10: Hourly | F10: 250 | G10: 18 | H10: =F10*G10 -> 4500 | I10: Transferred
A11: 10 | B11: 2025 | C11: May | D11: Abaza | E11: Hourly | F11: 400 | G11: 4 | H11: =F11*G11 -> 1600 | I11: Transferred
A12: 11 | B12: 2025 | C12: May | D12: Alaa Ashraf | E12: Hourly | F12: 100 | G12: 1.15 | H12: =F12*G12 -> 115 | I12: Transferred
A13: 12 | B13: 2025 | C13: May | D13: Nada Amin | E13: Hourly | F13: 150 | G13: 41.78 | H13: =F13*G13 -> 6267 | I13: Transferred
... A39: 38 | B39: 2025 | C39: September | D39: Tarek Mohamed | E39: Hourly | F39: 150 | G39: 6.19 | H39: =F39*G39 -> 928.5 | I39: Transferred
A40: 39 | B40: 2025 | C40: September | D40: Amal Hamdy | E40: Fulltime | G40: 0 | H40: 4000 | I40: Transferred
A41: 40 | B41: 2025 | C41: October | D41: Alaa Ashraf | E41: Hourly | F41: 100 | G41: 5 | H41: =F41*G41 -> 500 | I41: Transferred
A42: 41 | B42: 2025 | C42: October | D42: Nada Amin | E42: Hourly | F42: 150 | G42: 5.25 | H42: =F42*G42 -> 787.5 | I42: Transferred
A43: 42 | B43: 2025 | C43: October | D43: Yasseen Nouh | E43: Hourly | F43: 350 | G43: 46 | H43: =F43*G43 -> 16100 | I43: Transferred
A44: 43 | B44: 2025 | C44: October | D44: Amr Tarek | E44: Hourly | F44: 350 | G44: 67.5 | H44: =F44*G44 -> 23625 | I44: Transferred
A45: 44 | B45: 2025 | C45: October | D45: Tarek Mohamed | E45: Hourly | F45: 150 | G45: 39.3 | H45: =F45*G45 -> 5895 | I45: Transferred
A46: 45 | B46: 2025 | C46: October | D46: Amal Hamdy | E46: Fulltime | F46: 54.05 | G46: 111 | H46: 6000 | I46: Transferred
A47: 46 | B47: 2025 | C47: November | D47: Alaa Ashraf | E47: Hourly | F47: 100 | G47: 0 | H47: =F47*G47 -> 0 | I47: Transferred
A48: 47 | B48: 2025 | C48: November | D48: Nada Amin | E48: Hourly | F48: 150 | G48: 91 | H48: =F48*G48 -> 13650 | I48: Transferred
A49: 48 | B49: 2025 | C49: November | D49: Yasseen Nouh | E49: Hourly | F49: 350 | G49: 0 | H49: =F49*G49 -> 0 | I49: Transferred
A50: 49 | B50: 2025 | C50: November | D50: Amr Tarek | E50: Hourly | F50: 350 | G50: 65.75 | H50: =F50*G50 -> 23012.5 | I50: Transferred
A51: 50 | B51: 2025 | C51: November | D51: Tarek Mohamed | E51: Hourly | F51: 150 | G51: 25.5 | H51: =F51*G51 -> 3825 | I51: Transferred
A52: 51 | B52: 2025 | C52: November | D52: Amal Hamdy | E52: Fulltime | G52: 0 | H52: 6000 | I52: Transferred
A53: 52 | B53: 2025 | C53: December | D53: Alaa Ashraf | E53: Hourly | F53: 100 | G53: 2 | H53: =F53*G53 -> 200 | I53: Open
A54: 53 | B54: 2025 | C54: December | D54: Nada Amin | E54: Hourly | F54: 150 | G54: 35 | H54: =F54*G54 -> 5250 | I54: Transferred
A55: 54 | B55: 2025 | C55: December | D55: Yasseen Nouh | E55: Hourly | F55: 350 | G55: 41 | H55: =F55*G55 -> 14350 | I55: Transferred
A56: 55 | B56: 2025 | C56: December | D56: Amr Tarek | E56: Hourly | F56: 350 | G56: 77.14 | H56: =F56*G56 -> 26999 | I56: Transferred
A57: 56 | B57: 2025 | C57: December | D57: Tarek Mohamed | E57: Hourly | F57: 150 | G57: 25 | H57: =F57*G57 -> 3750 | I57: Transferred
A58: 57 | B58: 2025 | C58: December | D58: Amal Hamdy | E58: Fulltime | G58: 0 | H58: 6000 | I58: Transferred
A59: 58 | B59: 2025 | C59: December | D59: Anas Emad | E59: Part-time + Hourly | G59: 50 | H59: 12500 | I59: Transferred
A60: 59 | B60: 2026 | C60: January | D60: Alaa Ashraf | E60: Hourly | F60: 100 | G60: 2.5 | H60: =F60*G60 -> 250 | I60: Open
A61: 60 | B61: 2026 | C61: January | D61: Nada Amin | E61: Hourly | F61: 150 | G61: 81 | H61: =F61*G61 -> 12150 | I61: Transferred
A62: 61 | B62: 2026 | C62: January | D62: Yasseen Nouh | E62: Hourly | F62: 350 | G62: 27.1 | H62: =F62*G62 -> 9485 | I62: Transferred
A63: 62 | B63: 2026 | C63: January | D63: Amr Tarek | E63: Hourly | F63: 350 | G63: 66 | H63: =F63*G63 -> 23100 | I63: Transferred
A64: 63 | B64: 2026 | C64: January | D64: Tarek Mohamed | E64: Hourly | F64: 150 | G64: 22 | H64: =F64*G64 -> 3300 | I64: Transferred
A65: 64 | B65: 2026 | C65: January | D65: Amal Hamdy | E65: Fulltime | G65: 0 | H65: 6000 | I65: Transferred
...

Sheet Monthly Summary
A1: Name | B1: Mar 2025 | C1: Apr 2025 | D1: May 2025 | E1: Jun 2025 | F1: Jul 2025 | G1: Aug 2025 | H1: Sep 2025 | I1: Oct 2025 | J1: Nov 2025 | K1: Dec 2025 | L1: Jan 2026 | M1: Feb 2026
A2: Rana El Sobky | B2: =SUMIFS('Time Log'!H:H,'Time Log'!D:D,"Rana El Sobky",'Time Log'!C:C,"March") -> 2737.5 | C2: =SUMIFS('Time Log'!H:H,'Time Log'!D:D,"Rana El Sobky",'Time Log'!C:C,"April") -> 1500 | D2: =SUMIFS('Time Log'!H:H,'Time Log'!D:D,"Rana El Sobky",'Time Log'!C:C,"May") -> 4500 | E2: =SUMIFS('Time Log'!H:H,'Time Log'!D:D,"Rana El Sobky",'Time Log'!C:C,"June") -> 0 | F2: =SUMIFS('Time Log'!H:H,'Time Log'!D:D,"Rana El Sobky",'Time Log'!C:C,"July") -> 2292.5 | G2: =SUMIFS('Time Log'!H:H,'Time Log'!D:D,"Rana El Sobky",'Time Log'!C:C,"August") -> 1187.5 | H2: =SUMIFS('Time Log'!H:H,'Time Log'!D:D,"Rana El Sobky",'Time Log'!C:C,"September") -> 0 | I2: =SUMIFS('Time Log'!H:H,'Time Log'!D:D,"Rana El Sobky",'Time Log'!C:C,"October") -> 7040 | J2: =SUMIFS('Time Log'!H:H,'Time Log'!D:D,"Rana El Sobky",'Time Log'!C:C,"November") -> 0 | K2: =SUMIFS('Time Log'!H:H,'Time Log'!D:D,"Rana El Sobky",'Time Log'!C:C,"December") -> 0 | L2: =SUMIFS('Time Log'!H:H,'Time Log'!D:D,"Rana El Sobky",'Time Log'!C:C,"January") -> 0 | M2: =SUMIFS('Time Log'!H:H,'Time Log'!D:D,"Rana El Sobky",'Time Log'!C:C,"February") -> 0
A3: Abaza | B3: =SUMIFS('Time Log'!H:H,'Time Log'!D:D,"Abaza",'Time Log'!C:C,"March") -> 1125 | C3: =SUMIFS('Time Log'!H:H,'Time Log'!D:D,"Abaza",'Time Log'!C:C,"April") -> 1400 | D3: =SUMIFS('Time Log'!H:H,'Time Log'!D:D,"Abaza",'Time Log'!C:C,"May") -> 1600 | E3: =SUMIFS('Time Log'!H:H,'Time Log'!D:D,"Abaza",'Time Log'!C:C,"June") -> 1296 | F3: =SUMIFS('Time Log'!H:H,'Time Log'!D:D,"Abaza",'Time Log'!C:C,"July") -> 0 | G3: =SUMIFS('Time Log'!H:H,'Time Log'!D:D,"Abaza",'Time Log'!C:C,"August") -> 0 | H3: =SUMIFS('Time Log'!H:H,'Time Log'!D:D,"Abaza",'Time Log'!C:C,"September") -> 0 | I3: =SUMIFS('Time Log'!H:H,'Time Log'!D:D,"Abaza",'Time Log'!C:C,"October") -> 0 | J3: =SUMIFS('Time Log'!H:H,'Time Log'!D:D,"Abaza",'Time Log'!C:C,"November") -> 0 | K3: =SUMIFS('Time Log'!H:H,'Time Log'!D:D,"Abaza",'Time Log'!C:C,"December") -> 0 | L3: =SUMIFS('Time Log'!H:H,'Time Log'!D:D,"Abaza",'Time Log'!C:C,"January") -> 0 | M3: =SUMIFS('Time Log'!H:H,'Time Log'!D:D,"Abaza",'Time Log'!C:C,"February") -> 0
A4: Alaa Ashraf | B4: =SUMIFS('Time Log'!H:H,'Time Log'!D:D,"Alaa Ashraf",'Time Log'!C:C,"March") -> 0 | C4: =SUMIFS('Time Log'!H:H,'Time Log'!D:D,"Alaa Ashraf",'Time Log'!C:C,"April") -> 725 | D4: =SUMIFS('Time Log'!H:H,'Time Log'!D:D,"Alaa Ashraf",'Time Log'!C:C,"May") -> 115 | E4: =SUMIFS('Time Log'!H:H,'Time Log'!D:D,"Alaa Ashraf",'Time Log'!C:C,"June") -> 0 | F4: =SUMIFS('Time Log'!H:H,'Time Log'!D:D,"Alaa Ashraf",'Time Log'!C:C,"July") -> 1020 | G4: =SUMIFS('Time Log'!H:H,'Time Log'!D:D,"Alaa Ashraf",'Time Log'!C:C,"August") -> 959 | H4: =SUMIFS('Time Log'!H:H,'Time Log'!D:D,"Alaa Ashraf",'Time Log'!C:C,"September") -> 1020 | I4: =SUMIFS('Time Log'!H:H,'Time Log'!D:D,"Alaa Ashraf",'Time Log'!C:C,"October") -> 500 | J4: =SUMIFS('Time Log'!H:H,'Time Log'!D:D,"Alaa Ashraf",'Time Log'!C:C,"November") -> 0 | K4: =SUMIFS('Time Log'!H:H,'Time Log'!D:D,"Alaa Ashraf",'Time Log'!C:C,"December") -> 200 | L4: =SUMIFS('Time Log'!H:H,'Time Log'!D:D,"Alaa Ashraf",'Time Log'!C:C,"January") -> 250 | M4: =SUMIFS('Time Log'!H:H,'Time Log'!D:D,"Alaa Ashraf",'Time Log'!C:C,"February") -> 0
A5: Nada Amin | B5: =SUMIFS('Time Log'!H:H,'Time Log'!D:D,"Nada Amin",'Time Log'!C:C,"March") -> 0 | C5: =SUMIFS('Time Log'!H:H,'Time Log'!D:D,"Nada Amin",'Time Log'!C:C,"April") -> 2550 | D5: =SUMIFS('Time Log'!H:H,'Time Log'!D:D,"Nada Amin",'Time Log'!C:C,"May") -> 6267 | E5: =SUMIFS('Time Log'!H:H,'Time Log'!D:D,"Nada Amin",'Time Log'!C:C,"June") -> 0 | F5: =SUMIFS('Time Log'!H:H,'Time Log'!D:D,"Nada Amin",'Time Log'!C:C,"July") -> 2025 | G5: =SUMIFS('Time Log'!H:H,'Time Log'!D:D,"Nada Amin",'Time Log'!C:C,"August") -> 375 | H5: =SUMIFS('Time Log'!H:H,'Time Log'!D:D,"Nada Amin",'Time Log'!C:C,"September") -> 12285 | I5: =SUMIFS('Time Log'!H:H,'Time Log'!D:D,"Nada Amin",'Time Log'!C:C,"October") -> 787.5 | J5: =SUMIFS('Time Log'!H:H,'Time Log'!D:D,"Nada Amin",'Time Log'!C:C,"November") -> 13650 | K5: =SUMIFS('Time Log'!H:H,'Time Log'!D:D,"Nada Amin",'Time Log'!C:C,"December") -> 5250 | L5: =SUMIFS('Time Log'!H:H,'Time Log'!D:D,"Nada Amin",'Time Log'!C:C,"January") -> 12150 | M5: =SUMIFS('Time Log'!H:H,'Time Log'!D:D,"Nada Amin",'Time Log'!C:C,"February") -> 3427.5
A6: Ahmed Hamdy | B6: =SUMIFS('Time Log'!H:H,'Time Log'!D:D,"Ahmed Hamdy",'Time Log'!C:C,"March") -> 0 | C6: =SUMIFS('Time Log'!H:H,'Time Log'!D:D,"Ahmed Hamdy",'Time Log'!C:C,"April") -> 4500 | D6: =SUMIFS('Time Log'!H:H,'Time Log'!D:D,"Ahmed Hamdy",'Time Log'!C:C,"May") -> 0 | E6: =SUMIFS('Time Log'!H:H,'Time Log'!D:D,"Ahmed Hamdy",'Time Log'!C:C,"June") -> 0 | F6: =SUMIFS('Time Log'!H:H,'Time Log'!D:D,"Ahmed Hamdy",'Time Log'!C:C,"July") -> 0 | G6: =SUMIFS('Time Log'!H:H,'Time Log'!D:D,"Ahmed Hamdy",'Time Log'!C:C,"August") -> 0 | H6: =SUMIFS('Time Log'!H:H,'Time Log'!D:D,"Ahmed Hamdy",'Time Log'!C:C,"September") -> 0 | I6: =SUMIFS('Time Log'!H:H,'Time Log'!D:D,"Ahmed Hamdy",'Time Log'!C:C,"October") -> 0 | J6: =SUMIFS('Time Log'!H:H,'Time Log'!D:D,"Ahmed Hamdy",'Time Log'!C:C,"November") -> 0 | K6: =SUMIFS('Time Log'!H:H,'Time Log'!D:D,"Ahmed Hamdy",'Time Log'!C:C,"December") -> 0 | L6: =SUMIFS('Time Log'!H:H,'Time Log'!D:D,"Ahmed Hamdy",'Time Log'!C:C,"January") -> 0 | M6: =SUMIFS('Time Log'!H:H,'Time Log'!D:D,"Ahmed Hamdy",'Time Log'!C:C,"February") -> 0
A7: Yasseen Nouh | B7: =SUMIFS('Time Log'!H:H,'Time Log'!D:D,"Yasseen Nouh",'Time Log'!C:C,"March") -> 0 | C7: =SUMIFS('Time Log'!H:H,'Time Log'!D:D,"Yasseen Nouh",'Time Log'!C:C,"April") -> 0 | D7: =SUMIFS('Time Log'!H:H,'Time Log'!D:D,"Yasseen Nouh",'Time Log'!C:C,"May") -> 2800 | E7: =SUMIFS('Time Log'!H:H,'Time Log'!D:D,"Yasseen Nouh",'Time Log'!C:C,"June") -> 0 | F7: =SUMIFS('Time Log'!H:H,'Time Log'!D:D,"Yasseen Nouh",'Time Log'!C:C,"July") -> 3150 | G7: =SUMIFS('Time Log'!H:H,'Time Log'!D:D,"Yasseen Nouh",'Time Log'!C:C,"August") -> 10500 | H7: =SUMIFS('Time Log'!H:H,'Time Log'!D:D,"Yasseen Nouh",'Time Log'!C:C,"September") -> 23166.5 | I7: =SUMIFS('Time Log'!H:H,'Time Log'!D:D,"Yasseen Nouh",'Time Log'!C:C,"October") -> 16100 | J7: =SUMIFS('Time Log'!H:H,'Time Log'!D:D,"Yasseen Nouh",'Time Log'!C:C,"November") -> 5600 | K7: =SUMIFS('Time Log'!H:H,'Time Log'!D:D,"Yasseen Nouh",'Time Log'!C:C,"December") -> 14350 | L7: =SUMIFS('Time Log'!H:H,'Time Log'!D:D,"Yasseen Nouh",'Time Log'!C:C,"January") -> 9485 | M7: =SUMIFS('Time Log'!H:H,'Time Log'!D:D,"Yasseen Nouh",'Time Log'!C:C,"February") -> 32252.5
A8: Amr Tarek | B8: =SUMIFS('Time Log'!H:H,'Time Log'!D:D,"Amr Tarek",'Time Log'!C:C,"March") -> 0 | C8: =SUMIFS('Time Log'!H:H,'Time Log'!D:D,"Amr Tarek",'Time Log'!C:C,"April") -> 0 | D8: =SUMIFS('Time Log'!H:H,'Time Log'!D:D,"Amr Tarek",'Time Log'!C:C,"May") -> 0 | E8: =SUMIFS('Time Log'!H:H,'Time Log'!D:D,"Amr Tarek",'Time Log'!C:C,"June") -> 0 | F8: =SUMIFS('Time Log'!H:H,'Time Log'!D:D,"Amr Tarek",'Time Log'!C:C,"July") -> 4620 | G8: =SUMIFS('Time Log'!H:H,'Time Log'!D:D,"Amr Tarek",'Time Log'!C:C,"August") -> 19687.5 | H8: =SUMIFS('Time Log'!H:H,'Time Log'!D:D,"Amr Tarek",'Time Log'!C:C,"September") -> 25200 | I8: =SUMIFS('Time Log'!H:H,'Time Log'!D:D,"Amr Tarek",'Time Log'!C:C,"October") -> 23625 | J8: =SUMIFS('Time Log'!H:H,'Time Log'!D:D,"Amr Tarek",'Time Log'!C:C,"November") -> 23012.5 | K8: =SUMIFS('Time Log'!H:H,'Time Log'!D:D,"Amr Tarek",'Time Log'!C:C,"December") -> 26999 | L8: =SUMIFS('Time Log'!H:H,'Time Log'!D:D,"Amr Tarek",'Time Log'!C:C,"January") -> 23100 | M8: =SUMIFS('Time Log'!H:H,'Time Log'!D:D,"Amr Tarek",'Time Log'!C:C,"February") -> 19302.5
A9: Tarek Mohamed | B9: =SUMIFS('Time Log'!H:H,'Time Log'!D:D,"Tarek Mohamed",'Time Log'!C:C,"March") -> 0 | C9: =SUMIFS('Time Log'!H:H,'Time Log'!D:D,"Tarek Mohamed",'Time Log'!C:C,"April") -> 0 | D9: =SUMIFS('Time Log'!H:H,'Time Log'!D:D,"Tarek Mohamed",'Time Log'!C:C,"May") -> 0 | E9: =SUMIFS('Time Log'!H:H,'Time Log'!D:D,"Tarek Mohamed",'Time Log'!C:C,"June") -> 0 | F9: =SUMIFS('Time Log'!H:H,'Time Log'!D:D,"Tarek Mohamed",'Time Log'!C:C,"July") -> 0 | G9: =SUMIFS('Time Log'!H:H,'Time Log'!D:D,"Tarek Mohamed",'Time Log'!C:C,"August") -> 0 | H9: =SUMIFS('Time Log'!H:H,'Time Log'!D:D,"Tarek Mohamed",'Time Log'!C:C,"September") -> 928.5 | I9: =SUMIFS('Time Log'!H:H,'Time Log'!D:D,"Tarek Mohamed",'Time Log'!C:C,"October") -> 5895 | J9: =SUMIFS('Time Log'!H:H,'Time Log'!D:D,"Tarek Mohamed",'Time Log'!C:C,"November") -> 3825 | K9: =SUMIFS('Time Log'!H:H,'Time Log'!D:D,"Tarek Mohamed",'Time Log'!C:C,"December") -> 3750 | L9: =SUMIFS('Time Log'!H:H,'Time Log'!D:D,"Tarek Mohamed",'Time Log'!C:C,"January") -> 3300 | M9: =SUMIFS('Time Log'!H:H,'Time Log'!D:D,"Tarek Mohamed",'Time Log'!C:C,"February") -> 2812.5
A10: Amal Hamdy | B10: =SUMIFS('Time Log'!H:H,'Time Log'!D:D,"Amal Hamdy",'Time Log'!C:C,"March") -> 0 | C10: =SUMIFS('Time Log'!H:H,'Time Log'!D:D,"Amal Hamdy",'Time Log'!C:C,"April") -> 0 | D10: =SUMIFS('Time Log'!H:H,'Time Log'!D:D,"Amal Hamdy",'Time Log'!C:C,"May") -> 0 | E10: =SUMIFS('Time Log'!H:H,'Time Log'!D:D,"Amal Hamdy",'Time Log'!C:C,"June") -> 0 | F10: =SUMIFS('Time Log'!H:H,'Time Log'!D:D,"Amal Hamdy",'Time Log'!C:C,"July") -> 0 | G10: =SUMIFS('Time Log'!H:H,'Time Log'!D:D,"Amal Hamdy",'Time Log'!C:C,"August") -> 0 | H10: =SUMIFS('Time Log'!H:H,'Time Log'!D:D,"Amal Hamdy",'Time Log'!C:C,"September") -> 4000 | I10: =SUMIFS('Time Log'!H:H,'Time Log'!D:D,"Amal Hamdy",'Time Log'!C:C,"October") -> 6000 | J10: =SUMIFS('Time Log'!H:H,'Time Log'!D:D,"Amal Hamdy",'Time Log'!C:C,"November") -> 6000 | K10: =SUMIFS('Time Log'!H:H,'Time Log'!D:D,"Amal Hamdy",'Time Log'!C:C,"December") -> 6000 | L10: =SUMIFS('Time Log'!H:H,'Time Log'!D:D,"Amal Hamdy",'Time Log'!C:C,"January") -> 6000 | M10: =SUMIFS('Time Log'!H:H,'Time Log'!D:D,"Amal Hamdy",'Time Log'!C:C,"February") -> 6000
A11: Anas Emad | B11: =SUMIFS('Time Log'!H:H,'Time Log'!D:D,"Anas Emad",'Time Log'!C:C,"March") -> 0 | C11: =SUMIFS('Time Log'!H:H,'Time Log'!D:D,"Anas Emad",'Time Log'!C:C,"April") -> 0 | D11: =SUMIFS('Time Log'!H:H,'Time Log'!D:D,"Anas Emad",'Time Log'!C:C,"May") -> 0 | E11: =SUMIFS('Time Log'!H:H,'Time Log'!D:D,"Anas Emad",'Time Log'!C:C,"June") -> 0 | F11: =SUMIFS('Time Log'!H:H,'Time Log'!D:D,"Anas Emad",'Time Log'!C:C,"July") -> 0 | G11: =SUMIFS('Time Log'!H:H,'Time Log'!D:D,"Anas Emad",'Time Log'!C:C,"August") -> 0 | H11: =SUMIFS('Time Log'!H:H,'Time Log'!D:D,"Anas Emad",'Time Log'!C:C,"September") -> 0 | I11: =SUMIFS('Time Log'!H:H,'Time Log'!D:D,"Anas Emad",'Time Log'!C:C,"October") -> 0 | J11: =SUMIFS('Time Log'!H:H,'Time Log'!D:D,"Anas Emad",'Time Log'!C:C,"November") -> 0 | K11: =SUMIFS('Time Log'!H:H,'Time Log'!D:D,"Anas Emad",'Time Log'!C:C,"December") -> 12500 | L11: =SUMIFS('Time Log'!H:H,'Time Log'!D:D,"Anas Emad",'Time Log'!C:C,"January") -> 16870.75 | M11: =SUMIFS('Time Log'!H:H,'Time Log'!D:D,"Anas Emad",'Time Log'!C:C,"February") -> 12000
A12: Bahaa Mohamed | B12: =SUMIFS('Time Log'!H:H,'Time Log'!D:D,"Bahaa Mohamed",'Time Log'!C:C,"March") -> 0 | C12: =SUMIFS('Time Log'!H:H,'Time Log'!D:D,"Bahaa Mohamed",'Time Log'!C:C,"April") -> 0 | D12: =SUMIFS('Time Log'!H:H,'Time Log'!D:D,"Bahaa Mohamed",'Time Log'!C:C,"May") -> 0 | E12: =SUMIFS('Time Log'!H:H,'Time Log'!D:D,"Bahaa Mohamed",'Time Log'!C:C,"June") -> 0 | F12: =SUMIFS('Time Log'!H:H,'Time Log'!D:D,"Bahaa Mohamed",'Time Log'!C:C,"July") -> 0 | G12: =SUMIFS('Time Log'!H:H,'Time Log'!D:D,"Bahaa Mohamed",'Time Log'!C:C,"August") -> 0 | H12: =SUMIFS('Time Log'!H:H,'Time Log'!D:D,"Bahaa Mohamed",'Time Log'!C:C,"September") -> 0 | I12: =SUMIFS('Time Log'!H:H,'Time Log'!D:D,"Bahaa Mohamed",'Time Log'!C:C,"October") -> 0 | J12: =SUMIFS('Time Log'!H:H,'Time Log'!D:D,"Bahaa Mohamed",'Time Log'!C:C,"November") -> 0 | K12: =SUMIFS('Time Log'!H:H,'Time Log'!D:D,"Bahaa Mohamed",'Time Log'!C:C,"December") -> 0 | L12: =SUMIFS('Time Log'!H:H,'Time Log'!D:D,"Bahaa Mohamed",'Time Log'!C:C,"January") -> 0 | M12: =SUMIFS('Time Log'!H:H,'Time Log'!D:D,"Bahaa Mohamed",'Time Log'!C:C,"February") -> 16363.64
A13: Tools & Infrastructure (EGP)
A14: Figma | B14: 1140 | C14: 1140 | D14: 1140 | E14: 1140 | F14: 1140 | G14: 1140 | H14: 1140 | I14: 1140 | J14: 1140 | K14: 1140 | L14: 0 | M14: 0
A15: Lovable | B15: 0 | C15: 2500 | D15: 2500 | E15: 5000 | F15: 5000 | G15: 5000 | H15: 5000 | I15: 10000 | J15: 12500 | K15: 12500 | L15: 15000 | M15: 15000
A16: Google | B16: 0 | C16: 0 | D16: 0 | E16: 1100 | F16: 1100 | G16: 1100 | H16: 1100 | I16: 1100 | J16: 1100 | K16: 1100 | L16: 1100 | M16: 1100
A17: Zoho | B17: 500 | C17: 500 | D17: 500 | E17: 500 | F17: 500 | G17: 500 | H17: 500 | I17: 500 | J17: 500 | K17: 500 | L17: 500 | M17: 500
A18: Make | B18: 500 | C18: 500 | D18: 500 | E18: 500 | F18: 500 | G18: 500 | H18: 500 | I18: 500 | J18: 500 | K18: 500 | L18: 500 | M18: 500
A19: Canva | B19: 0 | C19: 0 | D19: 0 | E19: 0 | F19: 0 | G19: 0 | H19: 0 | I19: 0 | J19: 0 | K19: 2500 | L19: 0 | M19: 0
A20: ClickUp | B20: 7000 | C20: 0 | D20: 0 | E20: 0 | F20: 0 | G20: 2750 | H20: 0 | I20: 0 | J20: 0 | K20: 0 | L20: 0 | M20: 0
A21: Total Tools | B21: =SUM(B14:B20) -> 9140 | C21: =SUM(C14:C20) -> 4640 | D21: =SUM(D14:D20) -> 4640 | E21: =SUM(E14:E20) -> 8240 | F21: =SUM(F14:F20) -> 8240 | G21: =SUM(G14:G20) -> 10990 | H21: =SUM(H14:H20) -> 8240 | I21: =SUM(I14:I20) -> 13240 | ... M21: =SUM(M14:M20) -> 17100
A22: Total Team Costs | B22: =SUM(B2:B12) -> 3862.5 | C22: =SUM(C2:C12) -> 10675 | D22: =SUM(D2:D12) -> 15282 | E22: =SUM(E2:E12) -> 1296 | F22: =SUM(F2:F12) -> 13107.5 | G22: =SUM(G2:G12) -> 32709 | H22: =SUM(H2:H12) -> 66600 | I22: =SUM(I2:I12) -> 59947.5 | ... M22: =SUM(M2:M12) -> 92158.64
A23: Total Monthly Spend | B23: =B22+B21 -> 13002.5 | C23: =C22+C21 -> 15315 | D23: =D22+D21 -> 19922 | E23: =E22+E21 -> 9536 | F23: =F22+F21 -> 21347.5 | G23: =G22+G21 -> 43699 | H23: =H22+H21 -> 74840 | I23: =I22+I21 -> 73187.5 | ... M23: =M22+M21 -> 109258.64
A24: Cumulative Spend | B24: =B23 -> 13002.5 | C24: =B24+C23 -> 28317.5 | D24: =C24+D23 -> 48239.5 | E24: =D24+E23 -> 57775.5 | F24: =E24+F23 -> 79123 | G24: =F24+G23 -> 122822 | H24: =G24+H23 -> 197662 | I24: =H24+I23 -> 270849.5 | J24: =I24+J23 -> 338677 | ... M24: =L24+M23 -> 623480.39

Sheet Salary Tracker
A1: Name | B1: Base Salary (EGP) | C1: Mar 2025 | D1: Apr 2025 | E1: May 2025 | F1: Jun 2025 | G1: Jul 2025 | H1: Aug 2025 | I1: Sep 2025 | J1: Oct 2025 | K1: Nov 2025 | L1: Dec 2025 | M1: Jan 2026 | N1: Feb 2026
A2: Amal Hamdy | B2: 6000 | C2: =SUMIFS('Time Log'!H:H,'Time Log'!D:D,"Amal Hamdy",'Time Log'!C:C,"March") -> 0 | D2: =SUMIFS('Time Log'!H:H,'Time Log'!D:D,"Amal Hamdy",'Time Log'!C:C,"April") -> 0 | E2: =SUMIFS('Time Log'!H:H,'Time Log'!D:D,"Amal Hamdy",'Time Log'!C:C,"May") -> 0 | F2: =SUMIFS('Time Log'!H:H,'Time Log'!D:D,"Amal Hamdy",'Time Log'!C:C,"June") -> 0 | G2: =SUMIFS('Time Log'!H:H,'Time Log'!D:D,"Amal Hamdy",'Time Log'!C:C,"July") -> 0 | H2: =SUMIFS('Time Log'!H:H,'Time Log'!D:D,"Amal Hamdy",'Time Log'!C:C,"August") -> 0 | I2: =SUMIFS('Time Log'!H:H,'Time Log'!D:D,"Amal Hamdy",'Time Log'!C:C,"September") -> 4000 | J2: =SUMIFS('Time Log'!H:H,'Time Log'!D:D,"Amal Hamdy",'Time Log'!C:C,"October") -> 6000 | K2: =SUMIFS('Time Log'!H:H,'Time Log'!D:D,"Amal Hamdy",'Time Log'!C:C,"November") -> 6000 | L2: =SUMIFS('Time Log'!H:H,'Time Log'!D:D,"Amal Hamdy",'Time Log'!C:C,"December") -> 6000 | M2: =SUMIFS('Time Log'!H:H,'Time Log'!D:D,"Amal Hamdy",'Time Log'!C:C,"January") -> 6000 | N2: =SUMIFS('Time Log'!H:H,'Time Log'!D:D,"Amal Hamdy",'Time Log'!C:C,"February") -> 6000
A3: Anas Emad | B3: 12000 | C3: =SUMIFS('Time Log'!H:H,'Time Log'!D:D,"Anas Emad",'Time Log'!C:C,"March") -> 0 | D3: =SUMIFS('Time Log'!H:H,'Time Log'!D:D,"Anas Emad",'Time Log'!C:C,"April") -> 0 | E3: =SUMIFS('Time Log'!H:H,'Time Log'!D:D,"Anas Emad",'Time Log'!C:C,"May") -> 0 | F3: =SUMIFS('Time Log'!H:H,'Time Log'!D:D,"Anas Emad",'Time Log'!C:C,"June") -> 0 | G3: =SUMIFS('Time Log'!H:H,'Time Log'!D:D,"Anas Emad",'Time Log'!C:C,"July") -> 0 | H3: =SUMIFS('Time Log'!H:H,'Time Log'!D:D,"Anas Emad",'Time Log'!C:C,"August") -> 0 | I3: =SUMIFS('Time Log'!H:H,'Time Log'!D:D,"Anas Emad",'Time Log'!C:C,"September") -> 0 | J3: =SUMIFS('Time Log'!H:H,'Time Log'!D:D,"Anas Emad",'Time Log'!C:C,"October") -> 0 | K3: =SUMIFS('Time Log'!H:H,'Time Log'!D:D,"Anas Emad",'Time Log'!C:C,"November") -> 0 | L3: =SUMIFS('Time Log'!H:H,'Time Log'!D:D,"Anas Emad",'Time Log'!C:C,"December") -> 12500 | M3: =SUMIFS('Time Log'!H:H,'Time Log'!D:D,"Anas Emad",'Time Log'!C:C,"January") -> 16870.75 | N3: =SUMIFS('Time Log'!H:H,'Time Log'!D:D,"Anas Emad",'Time Log'!C:C,"February") -> 12000
A4: Bahaa Mohamed | B4: 30000 | C4: =SUMIFS('Time Log'!H:H,'Time Log'!D:D,"Bahaa Mohamed",'Time Log'!C:C,"March") -> 0 | D4: =SUMIFS('Time Log'!H:H,'Time Log'!D:D,"Bahaa Mohamed",'Time Log'!C:C,"April") -> 0 | E4: =SUMIFS('Time Log'!H:H,'Time Log'!D:D,"Bahaa Mohamed",'Time Log'!C:C,"May") -> 0 | F4: =SUMIFS('Time Log'!H:H,'Time Log'!D:D,"Bahaa Mohamed",'Time Log'!C:C,"June") -> 0 | G4: =SUMIFS('Time Log'!H:H,'Time Log'!D:D,"Bahaa Mohamed",'Time Log'!C:C,"July") -> 0 | H4: =SUMIFS('Time Log'!H:H,'Time Log'!D:D,"Bahaa Mohamed",'Time Log'!C:C,"August") -> 0 | I4: =SUMIFS('Time Log'!H:H,'Time Log'!D:D,"Bahaa Mohamed",'Time Log'!C:C,"September") -> 0 | J4: =SUMIFS('Time Log'!H:H,'Time Log'!D:D,"Bahaa Mohamed",'Time Log'!C:C,"October") -> 0 | K4: =SUMIFS('Time Log'!H:H,'Time Log'!D:D,"Bahaa Mohamed",'Time Log'!C:C,"November") -> 0 | L4: =SUMIFS('Time Log'!H:H,'Time Log'!D:D,"Bahaa Mohamed",'Time Log'!C:C,"December") -> 0 | M4: =SUMIFS('Time Log'!H:H,'Time Log'!D:D,"Bahaa Mohamed",'Time Log'!C:C,"January") -> 0 | N4: =SUMIFS('Time Log'!H:H,'Time Log'!D:D,"Bahaa Mohamed",'Time Log'!C:C,"February") -> 16363.64

Sheet Employment Rules
A1: Employment Type | B1: Definition | C1: Hours/Week | D1: Days Off/Year | E1: Payment Method
A2: Hourly | B2: Pay-per-hour based on logged hours | C2: Variable | D2: N/A | E2: Hours × Hourly Rate
A3: Fulltime | B3: 7 hours/day, 5 days/week | C3: 35 | D3: 21 | E3: Fixed monthly salary
A4: Part-time + Hourly | B4: Base monthly salary + extra hours at hourly rate | C4: Variable | D4: Per agreement | E4: Base salary + extra hours × rate
